[2024-09-02 06:05:24 +0000] [892426] [INFO] Starting gunicorn 23.0.0
[2024-09-02 06:05:24 +0000] [892426] [INFO] Listening at: http://127.0.0.1:8000 (892426)
[2024-09-02 06:05:24 +0000] [892426] [INFO] Using worker: sync
[2024-09-02 06:05:24 +0000] [892427] [INFO] Booting worker with pid: 892427
[2024-09-02 06:05:40 +0000] [892427] [ERROR] Exception in worker process
Traceback (most recent call last):
  File "/home/varun_saagar/StyleTTS2-Sillytavern-api/api.py", line 34, in <module>
    response = make_tts_request(data)
                                ^^^^
NameError: name 'data' is not defined

During handling of the above exception, another exception occurred:

Traceback (most recent call last):
  File "/home/varun_saagar/StyleTTS2-Sillytavern-api/styletts/lib/python3.11/site-packages/gunicorn/arbiter.py", line 608, in spawn_worker
    worker.init_process()
  File "/home/varun_saagar/StyleTTS2-Sillytavern-api/styletts/lib/python3.11/site-packages/gunicorn/workers/base.py", line 135, in init_process
    self.load_wsgi()
  File "/home/varun_saagar/StyleTTS2-Sillytavern-api/styletts/lib/python3.11/site-packages/gunicorn/workers/base.py", line 147, in load_wsgi
    self.wsgi = self.app.wsgi()
                ^^^^^^^^^^^^^^^
  File "/home/varun_saagar/StyleTTS2-Sillytavern-api/styletts/lib/python3.11/site-packages/gunicorn/app/base.py", line 66, in wsgi
    self.callable = self.load()
                    ^^^^^^^^^^^
  File "/home/varun_saagar/StyleTTS2-Sillytavern-api/styletts/lib/python3.11/site-packages/gunicorn/app/wsgiapp.py", line 57, in load
    return self.load_wsgiapp()
           ^^^^^^^^^^^^^^^^^^^
  File "/home/varun_saagar/StyleTTS2-Sillytavern-api/styletts/lib/python3.11/site-packages/gunicorn/app/wsgiapp.py", line 47, in load_wsgiapp
    return util.import_app(self.app_uri)
           ^^^^^^^^^^^^^^^^^^^^^^^^^^^^^
  File "/home/varun_saagar/StyleTTS2-Sillytavern-api/styletts/lib/python3.11/site-packages/gunicorn/util.py", line 370, in import_app
    mod = importlib.import_module(module)
          ^^^^^^^^^^^^^^^^^^^^^^^^^^^^^^^
  File "/usr/lib/python3.11/importlib/__init__.py", line 126, in import_module
    return _bootstrap._gcd_import(name[level:], package, level)
           ^^^^^^^^^^^^^^^^^^^^^^^^^^^^^^^^^^^^^^^^^^^^^^^^^^^^
  File "<frozen importlib._bootstrap>", line 1204, in _gcd_import
  File "<frozen importlib._bootstrap>", line 1176, in _find_and_load
  File "<frozen importlib._bootstrap>", line 1147, in _find_and_load_unlocked
  File "<frozen importlib._bootstrap>", line 690, in _load_unlocked
  File "<frozen importlib._bootstrap_external>", line 940, in exec_module
  File "<frozen importlib._bootstrap>", line 241, in _call_with_frames_removed
  File "/home/varun_saagar/StyleTTS2-Sillytavern-api/wsgi.py", line 1, in <module>
    from api import app
  File "/home/varun_saagar/StyleTTS2-Sillytavern-api/api.py", line 35, in <module>
    except CircuitBreakerError:
           ^^^^^^^^^^^^^^^^^^^
NameError: name 'CircuitBreakerError' is not defined
[2024-09-02 06:05:40 +0000] [892427] [INFO] Worker exiting (pid: 892427)
[2024-09-02 06:05:41 +0000] [892426] [ERROR] Worker (pid:892427) exited with code 3
[2024-09-02 06:05:41 +0000] [892426] [ERROR] Shutting down: Master
[2024-09-02 06:05:41 +0000] [892426] [ERROR] Reason: Worker failed to boot.
